<?xml version="1.0" encoding="utf-8"?><testsuites><testsuite name="pytest" errors="1" failures="0" skipped="0" tests="2" time="49.555" timestamp="2023-04-13T11:17:23.952117" hostname="NJCQ-DESK"><testcase classname="test_HomePage.TestHomePage" name="test_form_submission[get_data0]" time="26.989" /><testcase classname="pytest" name="internal" time="0.000"><error message="internal error">Traceback (most recent call last):
  File "C:\Users\User\AppData\Local\Programs\Python\Python310\lib\site-packages\_pytest\main.py", line 270, in wrap_session
    session.exitstatus = doit(config, session) or 0
  File "C:\Users\User\AppData\Local\Programs\Python\Python310\lib\site-packages\_pytest\main.py", line 324, in _main
    config.hook.pytest_runtestloop(session=session)
  File "C:\Users\User\AppData\Local\Programs\Python\Python310\lib\site-packages\pluggy\_hooks.py", line 265, in __call__
    return self._hookexec(self.name, self.get_hookimpls(), kwargs, firstresult)
  File "C:\Users\User\AppData\Local\Programs\Python\Python310\lib\site-packages\pluggy\_manager.py", line 80, in _hookexec
    return self._inner_hookexec(hook_name, methods, kwargs, firstresult)
  File "C:\Users\User\AppData\Local\Programs\Python\Python310\lib\site-packages\pluggy\_callers.py", line 60, in _multicall
    return outcome.get_result()
  File "C:\Users\User\AppData\Local\Programs\Python\Python310\lib\site-packages\pluggy\_result.py", line 60, in get_result
    raise ex[1].with_traceback(ex[2])
  File "C:\Users\User\AppData\Local\Programs\Python\Python310\lib\site-packages\pluggy\_callers.py", line 39, in _multicall
    res = hook_impl.function(*args)
  File "C:\Users\User\AppData\Local\Programs\Python\Python310\lib\site-packages\_pytest\main.py", line 349, in pytest_runtestloop
    item.config.hook.pytest_runtest_protocol(item=item, nextitem=nextitem)
  File "C:\Users\User\AppData\Local\Programs\Python\Python310\lib\site-packages\pluggy\_hooks.py", line 265, in __call__
    return self._hookexec(self.name, self.get_hookimpls(), kwargs, firstresult)
  File "C:\Users\User\AppData\Local\Programs\Python\Python310\lib\site-packages\pluggy\_manager.py", line 80, in _hookexec
    return self._inner_hookexec(hook_name, methods, kwargs, firstresult)
  File "C:\Users\User\AppData\Local\Programs\Python\Python310\lib\site-packages\pluggy\_callers.py", line 60, in _multicall
    return outcome.get_result()
  File "C:\Users\User\AppData\Local\Programs\Python\Python310\lib\site-packages\pluggy\_result.py", line 60, in get_result
    raise ex[1].with_traceback(ex[2])
  File "C:\Users\User\AppData\Local\Programs\Python\Python310\lib\site-packages\pluggy\_callers.py", line 39, in _multicall
    res = hook_impl.function(*args)
  File "C:\Users\User\AppData\Local\Programs\Python\Python310\lib\site-packages\_pytest\runner.py", line 112, in pytest_runtest_protocol
    runtestprotocol(item, nextitem=nextitem)
  File "C:\Users\User\AppData\Local\Programs\Python\Python310\lib\site-packages\_pytest\runner.py", line 125, in runtestprotocol
    rep = call_and_report(item, "setup", log)
  File "C:\Users\User\AppData\Local\Programs\Python\Python310\lib\site-packages\_pytest\runner.py", line 222, in call_and_report
    report: TestReport = hook.pytest_runtest_makereport(item=item, call=call)
  File "C:\Users\User\AppData\Local\Programs\Python\Python310\lib\site-packages\pluggy\_hooks.py", line 265, in __call__
    return self._hookexec(self.name, self.get_hookimpls(), kwargs, firstresult)
  File "C:\Users\User\AppData\Local\Programs\Python\Python310\lib\site-packages\pluggy\_manager.py", line 80, in _hookexec
    return self._inner_hookexec(hook_name, methods, kwargs, firstresult)
  File "C:\Users\User\AppData\Local\Programs\Python\Python310\lib\site-packages\pluggy\_callers.py", line 55, in _multicall
    gen.send(outcome)
  File "C:\Users\User\PycharmProjects1\PythonSeleniumFramework\tests\conftest.py", line 84, in pytest_runtest_makereport
    _capture_screenshot(file_name)
  File "C:\Users\User\PycharmProjects1\PythonSeleniumFramework\tests\conftest.py", line 100, in _capture_screenshot
    driver.get_screenshot_as_file(name)
  File "C:\Users\User\AppData\Local\Programs\Python\Python310\lib\site-packages\selenium\webdriver\remote\webdriver.py", line 929, in get_screenshot_as_file
    png = self.get_screenshot_as_png()
  File "C:\Users\User\AppData\Local\Programs\Python\Python310\lib\site-packages\selenium\webdriver\remote\webdriver.py", line 965, in get_screenshot_as_png
    return b64decode(self.get_screenshot_as_base64().encode("ascii"))
  File "C:\Users\User\AppData\Local\Programs\Python\Python310\lib\site-packages\selenium\webdriver\remote\webdriver.py", line 977, in get_screenshot_as_base64
    return self.execute(Command.SCREENSHOT)["value"]
  File "C:\Users\User\AppData\Local\Programs\Python\Python310\lib\site-packages\selenium\webdriver\remote\webdriver.py", line 444, in execute
    self.error_handler.check_response(response)
  File "C:\Users\User\AppData\Local\Programs\Python\Python310\lib\site-packages\selenium\webdriver\remote\errorhandler.py", line 249, in check_response
    raise exception_class(message, screen, stacktrace)
selenium.common.exceptions.InvalidSessionIdException: Message: Tried to run command without establishing a connection</error></testcase></testsuite></testsuites>